import mods.gregtech.multiblock.Builder;
import mods.gregtech.multiblock.FactoryBlockPattern;
import mods.gregtech.multiblock.RelativeDirection;
import mods.gregtech.multiblock.functions.IPatternBuilderFunction;
import mods.gregtech.IControllerTile;
import mods.gregtech.multiblock.CTPredicate;
import mods.gregtech.multiblock.IBlockPattern;
import mods.gregtech.recipe.FactoryRecipeMap;
import mods.gregtech.recipe.RecipeMap;
import mods.gregtech.recipe.functions.IRunOverclockingLogicFunction;
import mods.gregtech.recipe.IRecipeLogic;
import mods.gregtech.recipe.IRecipe;
 
global plasma_blast_furnace as RecipeMap = FactoryRecipeMap.start("plasma_blast_furnace")
    .maxInputs(6)
	.maxOutputs(6)
    .maxFluidInputs(3)
    .maxFluidOutputs(3)
    .build();
 
Builder.start("plasma_blast_furnace", 32000)
    .withPattern(function(controller as IControllerTile) as IBlockPattern {
        return FactoryBlockPattern.start()
            .aisle("                   AAA                                   ", "                                                         ", "                                                         ", "                                                         ", "                                                         ", "                                                         ", "                                                         ", "                                                         ", "                                                         ", "                                                         ", "                                                         ", "                                                         ", "                                                         ", "                                                         ", "                                                         ", "                                                         ", "                                                         ", "                                                         ", "                                                         ", "                                                         ", "                                                         ", "                                                         ", "                                                         ", "                                                         ", "                                                         ")
            .aisle("                  AAAAA                                  ", "                                                         ", "                                                         ", "                                                         ", "                                                         ", "                                                         ", "                                                         ", "                                                         ", "                                                         ", "                                                         ", "                                                         ", "                                                         ", "                                                         ", "                                                         ", "                                                         ", "                                                         ", "                                                         ", "                                                         ", "                                                         ", "                                                         ", "                                                         ", "                                                         ", "                                                         ", "                                                         ", "                                                         ")
            .aisle("                  AAAAA                                  ", "                   KKK                                   ", "                                                         ", "                                                         ", "                                                         ", "                                                         ", "                   AAA                                   ", "                   ZZZ                                   ", "                   ZZZ                                   ", "                   ZZZ                                   ", "                   AAA                                   ", "                                                         ", "                                                         ", "                                                         ", "                                                         ", "                                                         ", "                                                         ", "                                                         ", "                                                         ", "                                                         ", "                                                         ", "                                                         ", "                                                         ", "                                                         ", "                                                         ")
            .aisle("                AAAAAAAAA                                ", "                  KAAAK                                  ", "                   ZZZ                                   ", "                   ZZZ                                   ", "                   ZZZ                                   ", "                   AAA                                   ", "                  A   A                                  ", "                  Z   Z                                  ", "                  Z   Z                                  ", "                  Z   Z                                  ", "                  AYYYA                                  ", "                   AAA                                   ", "                   AAA                                   ", "                   AAA                                   ", "                                                         ", "                                                         ", "                                                         ", "                                                         ", "                                                         ", "                                                         ", "                                                         ", "                                                         ", "                                                         ", "                                                         ", "                                                         ")
            .aisle("                AAAAAAAAA                                ", "                  KAYAK                                  ", "                   Z Z                                   ", "                   Z Z                                   ", "                   Z Z                                   ", "                   A A                                   ", "                  A   A                                  ", "                  Z   Z                                  ", "                  Z   Z                                  ", "                  Z   Z                                  ", "                  AY YA                                  ", "                   A A                                   ", "                   A A                                   ", "                   A A                                   ", "                   LAL                                   ", "                                                         ", "                                                         ", "                                                         ", "                                                         ", "                                                         ", "                                                         ", "                                                         ", "                                                         ", "                                                         ", "                                                         ")
            .aisle("                AAAAAAAAA                                ", "                  KAAAK                                  ", "                   ZZZ                                   ", "                   ZZZ                                   ", "                   ZZZ                                   ", "                   AAA                                   ", "                  A   A                                  ", "                  Z   Z                                  ", "                  Z   Z                                  ", "                  Z   Z                                  ", "                  AYYYA                                  ", "                  KAAAK                                  ", "                  KAAAK                                  ", "                  KA AK                                  ", "                  KAAAK                                  ", "                  K   K                                  ", "                  K   K                                  ", "                  KKKKK                                  ", "                                                         ", "                                                         ", "                                                         ", "                                                         ", "                                                         ", "                                                         ", "                                                         ")
            .aisle("                  KAAAK                                  ", "                   KKK                                   ", "                                                         ", "                                                         ", "                                                         ", "                                                         ", "                   AAA                                   ", "                   ZZZ                                   ", "                   ZZZ                                   ", "                   ZZZ                                   ", "                   AAA                                   ", "                                                         ", "                   AAA                                   ", "                   R R                                   ", "                   LAL                                   ", "                                                         ", "                                                         ", "                  K   K                                  ", "                                                         ", "                                                         ", "                                                         ", "                                                         ", "                                                         ", "                                                         ", "                                                         ")
            .aisle("                  KKKKK                                  ", "                                                         ", "                                                         ", "                                                         ", "                                                         ", "                                                         ", "                                                         ", "                                                         ", "                                                         ", "                                                         ", "                                                         ", "                                                         ", "                   AAA                                   ", "                   R R                                   ", "                   LAL                                   ", "                   BBB                                   ", "                   BBB                                   ", "                  KBBBK                                  ", "                   BBB                                   ", "                  LLLLL                                  ", "                                                         ", "                                                         ", "                                                         ", "                                                         ", "                                                         ")
            .aisle("                  K   K                                  ", "                                                         ", "                                                         ", "                                                         ", "                                                         ", "                                                         ", "                                                         ", "                                                         ", "                                                         ", "                                                         ", "                                                         ", "                                                         ", "                   AAA                                   ", "                   A A                                   ", "                   LAL                                   ", "                   BGB                                   ", "                   BGB                                   ", "                  KBGBK                                  ", "                   AGAA                                  ", "                LLAGGGY                                  ", "                   AAAA                                  ", "                                                         ", "                                                         ", "                                                         ", "                                                         ")
            .aisle("                  K   K                                  ", "                                                         ", "                                                         ", "                                                         ", "                                                         ", "                                                         ", "                                                         ", "                                                         ", "                                                         ", "                                                         ", "                                                         ", "                                                         ", "                   AAA                                   ", "                   A A                                   ", "                   LAL                                   ", "                   BBB                                   ", "                   BBB                                   ", "                  KBBBK                                  ", "                AAABBB                                   ", "              LLGGGAAAA                                  ", "                AAA                                      ", "                                                         ", "                                                         ", "                                                         ", "                                                         ")
            .aisle("                  K   K                                  ", "                                                         ", "                                                         ", "                                                         ", "                                                         ", "                                                         ", "                                                         ", "                                                         ", "                                                         ", "                                                         ", "                                                         ", "                   AAA                                   ", "                  AYYYA                                  ", "                  AY YA                                  ", "                  AYYYA                                  ", "                   AAA                                   ", "                                                         ", "                  K   K                                  ", "              AA                                         ", "            LLGGAAA                                      ", "              AA                                         ", "                                                         ", "                                                         ", "                                                         ", "                                                         ")
            .aisle("                  K   K                                  ", "                                                         ", "                                                         ", "                                                         ", "                                                         ", "                                                         ", "                                                         ", "                                                         ", "                                                         ", "                                                         ", "                                                         ", "                   ZZZ                                   ", "                  Z   Z                                  ", "                  Z   Z                                  ", "                  Z   Z                                  ", "                   ZZZ                                   ", "                                                         ", "                  K   K                                  ", "            AA                                           ", "           LGGAA                                         ", "            AA                                           ", "                                                         ", "                                                         ", "                                                         ", "                                                         ")
            .aisle("                  K   K                                  ", "                                                         ", "                                                         ", "                                                         ", "                                                         ", "                                                         ", "                                                         ", "                                                         ", "                                                         ", "                                                         ", "                                                         ", "                   ZZZ                                   ", "                  Z   Z                                  ", "                  Z   Z                                  ", "                  Z   Z                                  ", "                   ZZZ                                   ", "                                                         ", "                  K   K                                  ", "            A                                            ", "           LGA                                           ", "            A                                            ", "                                                         ", "                                                         ", "                                                         ", "                                                         ")
            .aisle("                  K   K                                  ", "                                                         ", "                                                         ", "                                                         ", "                                                         ", "                                                         ", "                                                         ", "                                                         ", "                                                         ", "                                                         ", "                                                         ", "                   ZZZ                                   ", "                  Z   Z                                  ", "                  Z   Z                                  ", "                  Z   Z                                  ", "                   ZZZ                                   ", "                                                         ", "                  K   K                                  ", "           A                                             ", "          LGA                                            ", "           A                                             ", "                                                         ", "                                                         ", "                                                         ", "                                                         ")
            .aisle("                  KKKKK                                  ", "                                                         ", "                                                         ", "                                                         ", "                                                         ", "                                                         ", "                                                         ", "                                                         ", "                                                         ", "                                                         ", "                                                         ", "                   AAA                                   ", "                  AYYYA                                  ", "                  AY YA                                  ", "                  AYYYA                                  ", "                   AAA                                   ", "                                                         ", "                  K   K                                  ", "           A                                             ", "          LGA                                            ", "           A                                             ", "                                                         ", "                                                         ", "                                                         ", "                  AAAAA                                  ")
            .aisle("   AAA            KAAAK                       AAA        ", "                                                         ", "                                                         ", "                                                         ", "                                                         ", "                                                         ", "                                                         ", "                                                         ", "                                                         ", "                                                         ", "                                                         ", "                                                         ", "                   AAA                                   ", "                   A A                                   ", "                   AAA                                   ", "                                                         ", "                                                         ", "                  K   K                                  ", "          A                                              ", "         LGA                                             ", "          A                                              ", "                                                         ", "                                                         ", "                                                         ", "                 A  A  A                                 ")
            .aisle(" AAAAA           AAAAAAA                    AAAAAAA      ", "                   AAA                                   ", "                   ZZZ                                   ", "                   ZZZ                                   ", "                   ZZZ                                   ", "                   AAA                                   ", "                                                         ", "                                                         ", "                                                         ", "                                                         ", "                                                         ", "                                                         ", "                   AAA                        RRR        ", "                   A A                        RRR        ", "                   AAA                        RRR        ", "                                                         ", "                                                         ", "                  K   K                                  ", "          A                                              ", "         LGA                                             ", "          A                                              ", "                                                         ", "                                                         ", "                                                         ", "                A   A   A                                ")
            .aisle(" AAAAAKKKKKKKKKKKAAAAAAAKKKKKKKKKKKKKKKKKKKKAAAAAAA      ", "   KKK            AYYYA                       AAA        ", "                  Z   Z                       BBB        ", "                  Z   Z                       BBB        ", "                  Z   Z                       BBB        ", "                  A   A                       AAA        ", "   AAA             AAA                        AAA        ", "   ZZZ             ZZZ                        ZZZ        ", "   ZZZ             ZZZ                        ZZZ        ", "   ZZZ             ZZZ                        ZZZ        ", "   AAA             AAA                        AAA        ", "     K             BBB                        AAA        ", "     K     AZZZA  AAAAA        AZZZA         RYYYR       ", "     K     AZZZA  KAAAK        AZZZA         RYYYR       ", "     K     AZZZA  KAAAK        AZZZA         RYYYR       ", "     K            KBBBK        K   K         KAAA        ", "     K            KAAAK        K   K         KBBB        ", "     KKKKKKKKKKKKKKAAAK        K   K         KBBB        ", "          A       KZZZK        KKKKK         KBBB        ", "        LAGA      KRRRKLLLLLLLLLLLLLLLLLLLLLLBBBB        ", "          A       KZZZK                       BBB        ", "                  KAAAK                       BBB        ", "                  K   K                       BBB        ", "                  K   K                                  ", "               A  K A K  A                               ")
            .aisle("AAAAAAAAK      KAAAAAAAAAK                KAAAAAAAAAAAAAA", "  KAAAK          AY   YA                     A   AAA     ", "   ZZZ           Z     Z                     B   BBB     ", "   ZZZ           Z     Z                     B   B       ", "   ZZZ           Z     Z                     B   B       ", "   AAA           A     A                     A   A       ", "  A   A           A   A                      A   A       ", "  Z   Z           Z   Z                      Z   Z       ", "  Z   Z           Z   Z                      Z   Z       ", "  Z   Z           Z   Z                      Z   Z       ", "  AYYYA           AYYYA                      AYYYA       ", "   AAA     AZZZA  BGGGB        AZZZA         A   A       ", "   AAAAAAAAY   YAAAGGGAABBBAZZAY   YAZZABBBAAY   YAA     ", "   AAARRRAAY   YAAAGGGAABBBAZZAY   YAZZABBBAAY   YAAAA   ", "    AAAAAAAY   YAAAGGGAABBBAZZAY   YAZZABBBAAY   YAAAAAA ", "        BBBAZZZA  BGGGB        AZZZA        KAYYYA       ", "        BBB       AGGGA                      BAAAB       ", "     K  BBB       AYYYA                      BZZZB       ", "        BAB       Z   ZBBBBBBBBBBBBBBBBBBBBBBBZZZBBBBBBBB", "        LGA       R   RGGGGGGGGGGGGGGGGGGGGGGGGAAB       ", "         A        Z   ZBBBBBBBBBBBBBBBBBBBBBBBZZZBBBBBBBB", "                  A   A                      BZZZB       ", "                   RRR                       BAAABBBB    ", "                   AAA                        RRR        ", "               A    A    A                    AAA        ")
            .aisle("AAAAAAAAK      KAAAAAAAAAK                KAAAAAAAAAAAAAA", "  KAYAK          AY   YA                     A   GGGGLLLL", "   Z Z           Z     Z                     B   BBBA    ", "   Z Z           Z     Z                     B   B       ", "   Z Z           Z     Z                     B   B       ", "   AAA           A     A                     A   A       ", "  A   A           A   A                      A   A       ", "  Z   Z           Z   Z                      Z   Z       ", "  Z   Z           Z   Z                      Z   Z       ", "  Z   Z           Z   Z                      Z   Z       ", "  AY YA           AY YA                      AY YA       ", "   A A     AZZZA  BG GB        AZZZA         A   A       ", "   A AAAAAAY   YAAAG GAABBBAZZAY   YAZZABBBAAY   YAAA    ", "   A               G GGGGGGGGGGGGGGGGGGGGGGGGG   YAAAALLL", "    AAAAAAAY   YAAAG GAABBBAZZAY   YAZZABBBAAY   YAAAAAAA", "        BGBAZZZA  BG GB        AZZZA        KAY YA       ", "        BGB       AG GA                      BA AB       ", "     K  BGB       AY YA                      BZ ZB       ", "        BGB       Z   ZB                     BZ ZB       ", "        LGA       R   RBBBBBBBBBBBBBBBBBBBBBBBA AB       ", "         A        Z   ZB                     BZ ZB       ", "                  A   A                      BZ ZB       ", "                   RRR                       BAAAB       ", "                   AAA                        RRR        ", "               AAAAAAAAAAA                    AAA        ")
            .aisle("AAAAAAAAK      KAAAAAAAAAK                KAAAAAAAAAAAAAA", "  KAAAK          AY   YA                     A   AAA     ", "   ZZZ           Z     Z                     B   BBB     ", "   ZZZ           Z     Z                     B   B       ", "   ZZZ           Z     Z                     B   B       ", "   AAA           A     A                     A   A       ", "  A   A           A   A                      A   A       ", "  Z   Z           Z   Z                      Z   Z       ", "  Z   Z           Z   Z                      Z   Z       ", "  Z   Z           Z   Z                      Z   Z       ", "  AYYYA           AYYYA                      AYYYA       ", "   AAA     AZZZA  BGGGB        AZZZA         A   A       ", "   AAAAAAAAY   YAAAGGGAABBBAZZAY   YAZZABBBAAY   YAA     ", "   AAARRRAAY   YAAAGGGAABBBAZZAY   YAZZABBBAAY   YAAAA   ", "    AAAAAAAY   YAAAGGGAABBBAZZAY   YAZZABBBAAY   YAAAAAA ", "        BBBAZZZA  BGGGB        AZZZA        KAYYYA       ", "        BBB       AGGGA                      BAAAB       ", "     K  BBB       AYYYA                      BZZZB       ", "        BAB       Z   ZBBBBBBBBBBBBBBBBBBBBBBBZZZBBBBBBBB", "        LGA       R   RGGGGGGGGGGGGGGGGGGGGGGGGAAB       ", "         A        Z   ZBBBBBBBBBBBBBBBBBBBBBBBZZZBBBBBBBB", "                  A   A                      BZZZB       ", "                   RRR                       BAAABBBB    ", "                   AAA                        RRR        ", "               A    A    A                    AAA        ")
            .aisle(" AAAAAKKKKKKKKKKKAAAAAAAKKKKKKKKKKKKKKKKKKKKAAAAAAA      ", "   KKK            AYYYA                       AAA        ", "                  Z   Z                       BBB        ", "                  Z   Z                       BBB        ", "                  Z   Z                       BBB        ", "                  A   A                       AAA        ", "   AAA             AAA                        AAA        ", "   ZZZ             ZZZ                        ZZZ        ", "   ZZZ             ZZZ                        ZZZ        ", "   ZZZ             ZZZ                        ZZZ        ", "   AAA             AAA                        AAA        ", "     K             BBB                        AAA        ", "     K     AZZZA  AAAAA        AZZZA         RYYYR       ", "     K     AZZZA  KAAAK        AZZZA         RYYYR       ", "     K     AZZZA  KAAAK        AZZZA         RYYYR       ", "     K            KBBBK        K   K         KAAA        ", "     K            KAAAK        K   K         KBBB        ", "     KKKKKKKKKKKKKKAAAK        K   K         KBBB        ", "          A       KZZZK        KKKKK         KBBB        ", "        LAGA      KRRRKLLLLLLLLLLLLLLLLLLLLLLBBBB        ", "          A       KZZZK                       BBB        ", "                  KAAAK                       BBB        ", "                  K   K                       BBB        ", "                  K   K                                  ", "               A  K A K  A                               ")
            .aisle(" AAAAA           AAAAAAA                    AAAAAAA      ", "                   AAA                                   ", "                   ZZZ                                   ", "                   ZZZ                                   ", "                   ZZZ                                   ", "                   AAA                                   ", "                                                         ", "                                                         ", "                                                         ", "                                                         ", "                                                         ", "                                                         ", "                   AAA                        RRR        ", "                   A A                        RRR        ", "                   AAA                        RRR        ", "                                                         ", "                                                         ", "                  K   K                                  ", "          A                                              ", "         LGA                                             ", "          A                                              ", "                                                         ", "                                                         ", "                                                         ", "                A   A   A                                ")
            .aisle("   AAA            KAAAK                       AAA        ", "                                                         ", "                                                         ", "                                                         ", "                                                         ", "                                                         ", "                                                         ", "                                                         ", "                                                         ", "                                                         ", "                                                         ", "                                                         ", "                   AAA                                   ", "                   A A                                   ", "                   AAA                                   ", "                                                         ", "                                                         ", "                  K   K                                  ", "          A                                              ", "         LGA                                             ", "          A                                              ", "                                                         ", "                                                         ", "                                                         ", "                 A  A  A                                 ")
            .aisle("                  KKKKK                                  ", "                                                         ", "                                                         ", "                                                         ", "                                                         ", "                                                         ", "                                                         ", "                                                         ", "                                                         ", "                                                         ", "                                                         ", "                   AAA                                   ", "                  AYYYA                                  ", "                  AY YA                                  ", "                  AYYYA                                  ", "                   AAA                                   ", "                                                         ", "                  K   K                                  ", "           A                                             ", "          LGA                                            ", "           A                                             ", "                                                         ", "                                                         ", "                                                         ", "                  AAAAA                                  ")
            .aisle("                  K   K                                  ", "                                                         ", "                                                         ", "                                                         ", "                                                         ", "                                                         ", "                                                         ", "                                                         ", "                                                         ", "                                                         ", "                                                         ", "                   ZZZ                                   ", "                  Z   Z                                  ", "                  Z   Z                                  ", "                  Z   Z                                  ", "                   ZZZ                                   ", "                                                         ", "                  K   K                                  ", "           A                                             ", "          LGA                                            ", "           A                                             ", "                                                         ", "                                                         ", "                                                         ", "                                                         ")
            .aisle("                  K   K                                  ", "                                                         ", "                                                         ", "                                                         ", "                                                         ", "                                                         ", "                                                         ", "                                                         ", "                                                         ", "                                                         ", "                                                         ", "                   ZZZ                                   ", "                  Z   Z                                  ", "                  Z   Z                                  ", "                  Z   Z                                  ", "                   ZZZ                                   ", "                                                         ", "                  K   K                                  ", "            A                                            ", "           LGA                                           ", "            A                                            ", "                                                         ", "                                                         ", "                                                         ", "                                                         ")
            .aisle("                  K   K                                  ", "                                                         ", "                                                         ", "                                                         ", "                                                         ", "                                                         ", "                                                         ", "                                                         ", "                                                         ", "                                                         ", "                                                         ", "                   ZZZ                                   ", "                  Z   Z                                  ", "                  Z   Z                                  ", "                  Z   Z                                  ", "                   ZZZ                                   ", "                                                         ", "                  K   K                                  ", "            AA                                           ", "           LGGAA                                         ", "            AA                                           ", "                                                         ", "                                                         ", "                                                         ", "                                                         ")
            .aisle("                  K   K                                  ", "                                                         ", "                                                         ", "                                                         ", "                                                         ", "                                                         ", "                                                         ", "                                                         ", "                                                         ", "                                                         ", "                                                         ", "                   AAA                                   ", "                  AYYYA                                  ", "                  AY YA                                  ", "                  AYYYA                                  ", "                   AAA                                   ", "                                                         ", "                  K   K                                  ", "              AA                                         ", "            LLGGAAA                                      ", "              AA                                         ", "                                                         ", "                                                         ", "                                                         ", "                                                         ")
            .aisle("                  K   K                                  ", "                                                         ", "                                                         ", "                                                         ", "                                                         ", "                                                         ", "                                                         ", "                                                         ", "                                                         ", "                                                         ", "                                                         ", "                                                         ", "                   AAA                                   ", "                   A A                                   ", "                   LAL                                   ", "                   BBB                                   ", "                   BBB                                   ", "                  KBBBK                                  ", "                AAABBB                                   ", "              LLGGGAAAA                                  ", "                AAA                                      ", "                                                         ", "                                                         ", "                                                         ", "                                                         ")
            .aisle("                  K   K                                  ", "                                                         ", "                                                         ", "                                                         ", "                                                         ", "                                                         ", "                                                         ", "                                                         ", "                                                         ", "                                                         ", "                                                         ", "                                                         ", "                   AAA                                   ", "                   A A                                   ", "                   LAL                                   ", "                   BGB                                   ", "                   BGB                                   ", "                  KBGBK                                  ", "                   AGAA                                  ", "                LLAGGGY                                  ", "                   AAAA                                  ", "                                                         ", "                                                         ", "                                                         ", "                                                         ")
            .aisle("                  KKKKK                                  ", "                                                         ", "                                                         ", "                                                         ", "                                                         ", "                                                         ", "                                                         ", "                                                         ", "                                                         ", "                                                         ", "                                                         ", "                                                         ", "                   AAA                                   ", "                   R R                                   ", "                   LAL                                   ", "                   BBB                                   ", "                   BBB                                   ", "                  KBBBK                                  ", "                   BBB                                   ", "                  LLLLL                                  ", "                                                         ", "                                                         ", "                                                         ", "                                                         ", "                                                         ")
            .aisle("                  KAAAK                                  ", "                   KKK                                   ", "                                                         ", "                                                         ", "                                                         ", "                                                         ", "                   AAA                                   ", "                   ZZZ                                   ", "                   ZZZ                                   ", "                   ZZZ                                   ", "                   AAA                                   ", "                                                         ", "                   AAA                                   ", "                   R R                                   ", "                   LAL                                   ", "                                                         ", "                                                         ", "                  K   K                                  ", "                                                         ", "                                                         ", "                                                         ", "                                                         ", "                                                         ", "                                                         ", "                                                         ")
            .aisle("                AAAAAAAAA                                ", "                  KAAAK                                  ", "                   ZZZ                                   ", "                   ZZZ                                   ", "                   ZZZ                                   ", "                   AAA                                   ", "                  A   A                                  ", "                  Z   Z                                  ", "                  Z   Z                                  ", "                  Z   Z                                  ", "                  AYYYA                                  ", "                  KAAAK                                  ", "                  KAAAK                                  ", "                  KA AK                                  ", "                  KAAAK                                  ", "                  K   K                                  ", "                  K   K                                  ", "                  KKKKK                                  ", "                                                         ", "                                                         ", "                                                         ", "                                                         ", "                                                         ", "                                                         ", "                                                         ")
            .aisle("                AAAAAAAAA                                ", "                  KAYAK                                  ", "                   Z Z                                   ", "                   Z Z                                   ", "                   Z Z                                   ", "                   A A                                   ", "                  A   A                                  ", "                  Z   Z                                  ", "                  Z   Z                                  ", "                  Z   Z                                  ", "                  AY YA                                  ", "                   A A                                   ", "                   A A                                   ", "                   A A                                   ", "                   LAL                                   ", "                                                         ", "                                                         ", "                                                         ", "                                                         ", "                                                         ", "                                                         ", "                                                         ", "                                                         ", "                                                         ", "                                                         ")
            .aisle("                AAAAAAAAA                                ", "                  KAAAK                                  ", "                   ZZZ                                   ", "                   ZZZ                                   ", "                   ZZZ                                   ", "                   AAA                                   ", "                  A   A                                  ", "                  Z   Z                                  ", "                  Z   Z                                  ", "                  Z   Z                                  ", "                  AYYYA                                  ", "                   AAA                                   ", "                   AAA                                   ", "                   AAA                                   ", "                                                         ", "                                                         ", "                                                         ", "                                                         ", "                                                         ", "                                                         ", "                                                         ", "                                                         ", "                                                         ", "                                                         ", "                                                         ")
            .aisle("                 AAAAAAA                                 ", "                   KKK                                   ", "                                                         ", "                                                         ", "                                                         ", "                                                         ", "                   AAA                                   ", "                   ZZZ                                   ", "                   ZZZ                                   ", "                   ZZZ                                   ", "                   AAA                                   ", "                                                         ", "                                                         ", "                                                         ", "                                                         ", "                                                         ", "                                                         ", "                                                         ", "                                                         ", "                                                         ", "                                                         ", "                                                         ", "                                                         ", "                                                         ", "                                                         ")
            .aisle("                 AAAAAAA                                 ", "                                                         ", "                                                         ", "                                                         ", "                                                         ", "                                                         ", "                                                         ", "                                                         ", "                                                         ", "                                                         ", "                                                         ", "                                                         ", "                                                         ", "                                                         ", "                                                         ", "                                                         ", "                                                         ", "                                                         ", "                                                         ", "                                                         ", "                                                         ", "                                                         ", "                                                         ", "                                                         ", "                                                         ")
            .aisle("                   ACA                                   ", "                                                         ", "                                                         ", "                                                         ", "                                                         ", "                                                         ", "                                                         ", "                                                         ", "                                                         ", "                                                         ", "                                                         ", "                                                         ", "                                                         ", "                                                         ", "                                                         ", "                                                         ", "                                                         ", "                                                         ", "                                                         ", "                                                         ", "                                                         ", "                                                         ", "                                                         ", "                                                         ", "                                                         ")
            .where("C", controller.self())
            .where("G", <metastate:contenttweaker:stable_neutron_pipe_block>)
            .where("K", <metastate:gregtech:meta_block_frame_2010:4>)
            .where("Z", <metastate:gtqtcore:wire_coil:5>)
            .where("R", <metastate:gcym:unique_casing:3>)
            .where("B", <metastate:contenttweaker:cryogeniccasing>)
            .where("Y", <metastate:contenttweaker:gravitational_field_constraint_machine_block>)
			.where("L", <metastate:gregtech:blue_lamp:0>)
            .where("A", CTPredicate.states(<metastate:contenttweaker:unmeltable_machine_block>)
                | CTPredicate.abilities(<mte_ability:MAINTENANCE_HATCH>).setMinGlobalLimited(1).setMaxGlobalLimited(1).setPreviewCount(1)
                | CTPredicate.abilities(<mte_ability:INPUT_ENERGY>).setMinGlobalLimited(1).setMaxGlobalLimited(2).setPreviewCount(1)
                | CTPredicate.abilities(<mte_ability:IMPORT_ITEMS>).setMinGlobalLimited(1).setMaxGlobalLimited(3).setPreviewCount(1)
                | CTPredicate.abilities(<mte_ability:IMPORT_FLUIDS>).setMinGlobalLimited(1).setMaxGlobalLimited(3).setPreviewCount(1)
			    | CTPredicate.abilities(<mte_ability:EXPORT_ITEMS>).setMinGlobalLimited(1).setMaxGlobalLimited(3).setPreviewCount(1)
                | CTPredicate.abilities(<mte_ability:EXPORT_FLUIDS>).setMinGlobalLimited(1).setMaxGlobalLimited(3).setPreviewCount(1)
            )
            .where(" ", CTPredicate.getAir())
        .build();
    } as IPatternBuilderFunction)
    .withRecipeMap(plasma_blast_furnace)
    .withBaseTexture(<metastate:contenttweaker:unmeltable_machine_block>)
    .buildAndRegister();
